Workbook
Name SegmentaciónDeDatos_estado_crm: #N/A
Name SegmentaciónDeDatos_estado_crm1: #N/A
Name SegmentaciónDeDatos_estado_crm2: #N/A
Name SegmentaciónDeDatos_FAMILIA: #N/A
Name SegmentaciónDeDatos_FAMILIA1: #N/A
Name SegmentaciónDeDatos_FAMILIA2: #N/A
Name SegmentaciónDeDatos_LINEA: #N/A
Name SegmentaciónDeDatos_LINEA1: #N/A
Name SegmentaciónDeDatos_LINEA2: #N/A
Name SegmentaciónDeDatos_Mes_Entrega: #N/A
Name SegmentaciónDeDatos_Mes_Entrega1: #N/A
Name SegmentaciónDeDatos_Mes_Entrega2: #N/A
Name SegmentaciónDeDatos_oportunidad: #N/A
Name SegmentaciónDeDatos_oportunidad1: #N/A
Name SegmentaciónDeDatos_regional: #N/A

Sheet baseDatos
A1: pedido | B1: cliente | C1: tipo_producto | D1: oportunidad | E1: razon_anulacion | F1: f_cotizacion | G1: f_pedido | H1: f_comercial | I1: f_diseno | J1: f_produccion | K1: f_despachos | L1: f_instalacion | M1: fe_comercial | N1: fe_diseno | O1: fe_produccion | P1: fe_despachos | Q1: fe_instalacion | R1: estado | S1: regional | T1: id_producto | U1: producto | V1: color | W1: color_estructura | X1: cantidad | Y1: largo | Z1: alto | AA1: proyeccion | AB1: valor_total | AC1: estado_crm | AD1: FAMILIA | AE1: LINEA | AF1: Mes Entrega
A2: 13209 | B2: ENRIQUE AMOROCHO CORTEZ | C2: MUEBLES CC CUBRIMIENTOS | D2: 0 | F2: 2024-09-25 | G2: 2024-10-05 | H2: 2024-10-08 09:54:52 | I2: 0000-00-00 00:00:00 | J2: 2024-10-15 00:04:14 | K2: 2024-10-15 14:12:21 | L2: 0000-00-00 00:00:00 | M2: 2024-10-08 | N2: 2024-10-08 | O2: 2024-10-10 | P2: 2024-10-11 | Q2: 2024-10-11 | R2: Aprobado Despachos | S2: Bogota | T2: 98731 | U2: ACOPLE DESPL. SUP. MASTIL. SOMBR. ROMA. | X2: 1 | Y2: 0 | Z2: 0 | AA2: 0 | AB2: 33400 | AC2: FINALIZADO | AD2: =+VLOOKUP(T2,items!$A$2:$D$1255,4,0) -> 0 | AE2: =+VLOOKUP(T2,Tabla1[],5,0) -> 0 | AF2: =+MONTH(O2) -> 10
A3: 13209 | B3: ENRIQUE AMOROCHO CORTEZ | C3: MUEBLES CC CUBRIMIENTOS | D3: 0 | F3: 2024-09-25 | G3: 2024-10-05 | H3: 2024-10-08 09:54:52 | I3: 0000-00-00 00:00:00 | J3: 2024-10-15 00:04:14 | K3: 2024-10-15 14:12:21 | L3: 0000-00-00 00:00:00 | M3: 2024-10-08 | N3: 2024-10-08 | O3: 2024-10-10 | P3: 2024-10-11 | Q3: 2024-10-11 | R3: Aprobado Despachos | S3: Bogota | T3: REP045 | U3: REPARACION SOMBRILLA MANO OBRA | X3: 1 | Y3: 0 | Z3: 0 | AA3: 0 | AB3: 280000 | AC3: FINALIZADO | AD3: =+VLOOKUP(T3,items!$A$2:$D$1255,4,0) -> 0 | AE3: =+VLOOKUP(T3,Tabla1[],5,0) -> 0 | AF3: =+MONTH(O3) -> 10
A4: 13209 | B4: ENRIQUE AMOROCHO CORTEZ | C4: MUEBLES CC CUBRIMIENTOS | D4: 0 | F4: 2024-09-25 | G4: 2024-10-05 | H4: 2024-10-08 09:54:52 | I4: 0000-00-00 00:00:00 | J4: 2024-10-15 00:04:14 | K4: 2024-10-15 14:12:21 | L4: 0000-00-00 00:00:00 | M4: 2024-10-08 | N4: 2024-10-08 | O4: 2024-10-10 | P4: 2024-10-11 | Q4: 2024-10-11 | R4: Aprobado Despachos | S4: Bogota | T4: SERV08 | U4: SERVICIO VIATICOSINSTALACION MUEBLES | X4: 1 | Y4: 0 | Z4: 0 | AA4: 0 | AB4: 150000 | AC4: FINALIZADO | AD4: =+VLOOKUP(T4,items!$A$2:$D$1255,4,0) -> #N/A | AE4: =+VLOOKUP(T4,Tabla1[],5,0) -> #N/A | AF4: =+MONTH(O4) -> 10
A5: 52365 | B5: JORGE VASQUEZ | C5: MUEBLES CC CUBRIMIENTOS | D5: 0 | F5: 2025-06-04 | G5: 2025-06-04 | H5: 2020-07-06 09:16:22 | I5: 0000-00-00 00:00:00 | J5: 2020-08-03 10:09:35 | K5: 2020-08-03 10:10:06 | L5: 2020-11-13 11:37:46 | M5: 2020-07-03 | N5: 2020-07-07 | O5: 2020-07-30 | P5: 2020-08-04 | Q5: 2020-08-06 | R5: Aprobado Instalación | S5: Medellin | T5: 15477 | U5: MESA DE CENTRO JAPON ALUTECA 1*1(TA) | V5: No Aplica | X5: 1 | Y5: 0 | Z5: 0 | AA5: 0 | AB5: 1848739 | AC5: FINALIZADO | AD5: =+VLOOKUP(T5,items!$A$2:$D$1255,4,0) -> MUEBLES | AE5: =+VLOOKUP(T5,Tabla1[],5,0) -> 0 | AF5: =+MONTH(O5) -> 7
A6: 52365 | B6: JORGE VASQUEZ | C6: MUEBLES CC CUBRIMIENTOS | D6: 0 | F6: 2025-06-04 | G6: 2025-06-04 | H6: 2020-07-06 09:16:22 | I6: 0000-00-00 00:00:00 | J6: 2020-08-03 10:09:35 | K6: 2020-08-03 10:10:06 | L6: 2020-11-13 11:37:46 | M6: 2020-07-03 | N6: 2020-07-07 | O6: 2020-07-30 | P6: 2020-08-04 | Q6: 2020-08-06 | R6: Aprobado Instalación | S6: Medellin | T6: 15479 | U6: SOFA JAPON ALUTECA TRES PUESTOS C/C | V6: No Aplica | X6: 1 | Y6: 0 | Z6: 0 | AA6: 0 | AB6: 4075630 | AC6: FINALIZADO | AD6: =+VLOOKUP(T6,items!$A$2:$D$1255,4,0) -> MUEBLES | AE6: =+VLOOKUP(T6,Tabla1[],5,0) -> 0 | AF6: =+MONTH(O6) -> 7
A7: 52365 | B7: JORGE VASQUEZ | C7: MUEBLES CC CUBRIMIENTOS | D7: 0 | F7: 2025-06-04 | G7: 2025-06-04 | H7: 2020-07-06 09:16:22 | I7: 0000-00-00 00:00:00 | J7: 2020-08-03 10:09:35 | K7: 2020-08-03 10:10:06 | L7: 2020-11-13 11:37:46 | M7: 2020-07-03 | N7: 2020-07-07 | O7: 2020-07-30 | P7: 2020-08-04 | Q7: 2020-08-06 | R7: Aprobado Instalación | S7: Medellin | T7: 15481 | U7: POLTRONA JAPON ALUTECA C/C | V7: No Aplica | X7: 2 | Y7: 0 | Z7: 0 | AA7: 0 | AB7: 5294118 | AC7: FINALIZADO | AD7: =+VLOOKUP(T7,items!$A$2:$D$1255,4,0) -> MUEBLES | AE7: =+VLOOKUP(T7,Tabla1[],5,0) -> 0 | AF7: =+MONTH(O7) -> 7
A8: 52365 | B8: JORGE VASQUEZ | C8: MUEBLES CC CUBRIMIENTOS | D8: 0 | F8: 2025-06-04 | G8: 2025-06-04 | H8: 2020-07-06 09:16:22 | I8: 0000-00-00 00:00:00 | J8: 2020-08-03 10:09:35 | K8: 2020-08-03 10:10:06 | L8: 2020-11-13 11:37:46 | M8: 2020-07-03 | N8: 2020-07-07 | O8: 2020-07-30 | P8: 2020-08-04 | Q8: 2020-08-06 | R8: Aprobado Instalación | S8: Medellin | T8: 17 | U8: FLETES | V8: No Aplica | X8: 1 | Y8: 0 | Z8: 0 | AA8: 0 | AB8: 0 | AC8: FINALIZADO | AD8: =+VLOOKUP(T8,items!$A$2:$D$1255,4,0) -> #N/A | AE8: =+VLOOKUP(T8,Tabla1[],5,0) -> #N/A | AF8: =+MONTH(O8) -> 7
A9: 53753 | B9: PLAZA LA SERREZUELA SAS | C9: CUBRIMIENTO | D9: 0 | F9: 2025-01-17 | G9: 2025-02-26 | H9: 2025-03-21 14:00:31 | I9: 2025-04-12 07:35:14 | J9: 2025-04-24 11:45:42 | K9: 2025-04-28 08:23:55 | L9: 2025-08-20 09:23:51 | M9: 2025-03-05 | N9: 2025-04-10 | O9: 2025-04-24 | P9: 2025-04-30 | Q9: 2025-05-10 | R9: Aprobado Instalación | S9: Barranquilla | T9: 19353 | U9: PASADOR PUERTA CONICO P/FLEXIGLASS | X9: 2 | Y9: 0 | Z9: 0 | AA9: 0 | AB9: 5000 | AC9: FINALIZADO | AD9: =+VLOOKUP(T9,items!$A$2:$D$1255,4,0) -> 0 | AE9: =+VLOOKUP(T9,Tabla1[],5,0) -> 0 | AF9: =+MONTH(O9) -> 4
A10: 53753 | B10: PLAZA LA SERREZUELA SAS | C10: CUBRIMIENTO | D10: 0 | F10: 2025-01-17 | G10: 2025-02-26 | H10: 2025-03-21 14:00:31 | I10: 2025-04-12 07:35:14 | J10: 2025-04-24 11:45:42 | K10: 2025-04-28 08:23:55 | L10: 2025-08-20 09:23:51 | M10: 2025-03-05 | N10: 2025-04-10 | O10: 2025-04-24 | P10: 2025-04-30 | Q10: 2025-05-10 | R10: Aprobado Instalación | S10: Barranquilla | T10: FGLASS01 | U10: FLEXIGLASS 10 mm | W10: Blanco Señal - RAL 9003 | X10: 1 | Y10: 1500 | Z10: 3000 | AA10: 0 | AB10: 3703617 | AC10: FINALIZADO | AD10: =+VLOOKUP(T10,items!$A$2:$D$1255,4,0) -> FLEXIGLASS | AE10: =+VLOOKUP(T10,Tabla1[],5,0) -> 0 | AF10: =+MONTH(O10) -> 4
A11: 53753 | B11: PLAZA LA SERREZUELA SAS | C11: CUBRIMIENTO | D11: 0 | F11: 2025-01-17 | G11: 2025-02-26 | H11: 2025-03-21 14:00:31 | I11: 2025-04-12 07:35:14 | J11: 2025-04-24 11:45:42 | K11: 2025-04-28 08:23:55 | L11: 2025-08-20 09:23:51 | M11: 2025-03-05 | N11: 2025-04-10 | O11: 2025-04-24 | P11: 2025-04-30 | Q11: 2025-05-10 | R11: Aprobado Instalación | S11: Barranquilla | T11: FGLASS01 | U11: FLEXIGLASS 10 mm | W11: Blanco Señal - RAL 9003 | X11: 1 | Y11: 1500 | Z11: 3000 | AA11: 0 | AB11: 3703617 | AC11: FINALIZADO | AD11: =+VLOOKUP(T11,items!$A$2:$D$1255,4,0) -> FLEXIGLASS | AE11: =+VLOOKUP(T11,Tabla1[],5,0) -> 0 | AF11: =+MONTH(O11) -> 4
A12: 53753 | B12: PLAZA LA SERREZUELA SAS | C12: CUBRIMIENTO | D12: 0 | F12: 2025-01-17 | G12: 2025-02-26 | H12: 2025-03-21 14:00:31 | I12: 2025-04-12 07:35:14 | J12: 2025-04-24 11:45:42 | K12: 2025-04-28 08:23:55 | L12: 2025-08-20 09:23:51 | M12: 2025-03-05 | N12: 2025-04-10 | O12: 2025-04-24 | P12: 2025-04-30 | Q12: 2025-05-10 | R12: Aprobado Instalación | S12: Barranquilla | T12: SERV03 | U12: SERVICIO VIATICOSINSTALACION CUBRIMIENT | X12: 1 | Y12: 0 | Z12: 0 | AA12: 0 | AB12: 3400000 | AC12: FINALIZADO | AD12: =+VLOOKUP(T12,items!$A$2:$D$1255,4,0) -> #N/A | AE12: =+VLOOKUP(T12,Tabla1[],5,0) -> #N/A | AF12: =+MONTH(O12) -> 4
A13: 59320 | B13: JOSE PRUEBA MALDONADO PRUEBA | C13: MUEBLES CC CUBRIMIENTOS | D13: 0 | F13: 2025-07-16 | G13: 2025-03-04 | H13: 2025-04-29 10:34:59 | I13: 2025-04-29 11:05:19 | J13: 2025-04-30 15:57:46 | K13: 2025-04-29 13:34:55 | L13: 2025-04-29 13:35:01 | M13: 2025-03-05 | N13: 2025-03-13 | O13: 2025-04-08 | P13: 2025-04-10 | Q13: 2025-04-18 | R13: COTIZADO | S13: Cali | T13: 2043 | U13: MESA BISTRO 0.70*0.70 C/BM (TL) | W13: Color Aluminio Anodizado - RAL 9006 | X13: 1 | Y13: 0 | Z13: 0 | AA13: 0 | AB13: 883696 | AC13: FINALIZADO | AD13: =+VLOOKUP(T13,items!$A$2:$D$1255,4,0) -> MUEBLES | AE13: =+VLOOKUP(T13,Tabla1[],5,0) -> 0 | AF13: =+MONTH(O13) -> 4
A14: 59320 | B14: JOSE PRUEBA MALDONADO PRUEBA | C14: MUEBLES CC CUBRIMIENTOS | D14: 0 | F14: 2025-07-16 | G14: 2025-03-04 | H14: 2025-04-29 10:34:59 | I14: 2025-04-29 11:05:19 | J14: 2025-04-30 15:57:46 | K14: 2025-04-29 13:34:55 | L14: 2025-04-29 13:35:01 | M14: 2025-03-05 | N14: 2025-03-13 | O14: 2025-04-08 | P14: 2025-04-10 | Q14: 2025-04-18 | R14: COTIZADO | S14: Cali | T14: 2043 | U14: MESA BISTRO 0.70*0.70 C/BM (TL) | W14: Color Aluminio Anodizado - RAL 9006 | X14: 1 | Y14: 0 | Z14: 0 | AA14: 0 | AB14: 883696 | AC14: FINALIZADO | AD14: =+VLOOKUP(T14,items!$A$2:$D$1255,4,0) -> MUEBLES | AE14: =+VLOOKUP(T14,Tabla1[],5,0) -> 0 | AF14: =+MONTH(O14) -> 4
A15: 59320 | B15: JOSE PRUEBA MALDONADO PRUEBA | C15: MUEBLES CC CUBRIMIENTOS | D15: 0 | F15: 2025-07-16 | G15: 2025-03-04 | H15: 2025-04-29 10:34:59 | I15: 2025-04-29 11:05:19 | J15: 2025-04-30 15:57:46 | K15: 2025-04-29 13:34:55 | L15: 2025-04-29 13:35:01 | M15: 2025-03-05 | N15: 2025-03-13 | O15: 2025-04-08 | P15: 2025-04-10 | Q15: 2025-04-18 | R15: COTIZADO | S15: Cali | T15: PFAT07 | U15: PERGOLA FIJA ACEROTECA GRANDE | W15: Negro Señales - RAL 9004 | X15: 1 | Y15: 6000 | Z15: 0 | AA15: 4000 | AB15: 27803358 | AC15: FINALIZADO | AD15: =+VLOOKUP(T15,items!$A$2:$D$1255,4,0) -> PERGOLA | AE15: =+VLOOKUP(T15,Tabla1[],5,0) -> PERGOLA FIJA | AF15: =+MONTH(O15) -> 4
A16: 59320 | B16: JOSE PRUEBA MALDONADO PRUEBA | C16: MUEBLES CC CUBRIMIENTOS | D16: 0 | F16: 2025-07-16 | G16: 2025-03-04 | H16: 2025-04-29 10:34:59 | I16: 2025-04-29 11:05:19 | J16: 2025-04-30 15:57:46 | K16: 2025-04-29 13:34:55 | L16: 2025-04-29 13:35:01 | M16: 2025-03-05 | N16: 2025-03-13 | O16: 2025-04-08 | P16: 2025-04-10 | Q16: 2025-04-18 | R16: COTIZADO | S16: Cali | T16: PLAM05 | U16: MAXI PERGOLAM CON POSTES | W16: Aluminio Anodizado | X16: 1 | Y16: 5000 | Z16: 0 | AA16: 5000 | AB16: 71526140 | AC16: FINALIZADO | AD16: =+VLOOKUP(T16,items!$A$2:$D$1255,4,0) -> PERGOLA | AE16: =+VLOOKUP(T16,Tabla1[],5,0) -> MAXI PERGOLAM | AF16: =+MONTH(O16) -> 4
A17: 63598 | B17: hotel casablanca san andres sas | C17: CUBRIMIENTO | D17: 0 | F17: 2024-11-14 | G17: 2024-11-15 | H17: 2024-11-15 16:36:57 | I17: 0000-00-00 00:00:00 | J17: 2024-11-16 12:15:56 | K17: 2024-11-16 12:16:30 | L17: 0000-00-00 00:00:00 | M17: 2024-11-19 | N17: 2024-11-19 | O17: 2024-11-21 | P17: 2024-11-22 | Q17: 2024-11-22 | R17: Aprobado Facturacion | S17: Virtual | T17: 18013 | U17: TORN PRIS 8mmX8 DIAM P/FLEXIGLASS PLUS | X17: 190 | Y17: 0 | Z17: 0 | AA17: 0 | AB17: 237500 | AC17: FINALIZADO | AD17: =+VLOOKUP(T17,items!$A$2:$D$1255,4,0) -> 0 | AE17: =+VLOOKUP(T17,Tabla1[],5,0) -> 0 | AF17: =+MONTH(O17) -> 11
A18: 63598 | B18: hotel casablanca san andres sas | C18: CUBRIMIENTO | D18: 0 | F18: 2024-11-14 | G18: 2024-11-15 | H18: 2024-11-15 16:36:57 | I18: 0000-00-00 00:00:00 | J18: 2024-11-16 12:15:56 | K18: 2024-11-16 12:16:30 | L18: 0000-00-00 00:00:00 | M18: 2024-11-19 | N18: 2024-11-19 | O18: 2024-11-21 | P18: 2024-11-22 | Q18: 2024-11-22 | R18: Aprobado Facturacion | S18: Virtual | T18: 18447 | U18: FG+STACION SUPERIOR PUERTA (DAP1720) | X18: 2 | Y18: 0 | Z18: 0 | AA18: 0 | AB18: 9000 | AC18: FINALIZADO | AD18: =+VLOOKUP(T18,items!$A$2:$D$1255,4,0) -> 0 | AE18: =+VLOOKUP(T18,Tabla1[],5,0) -> 0 | AF18: =+MONTH(O18) -> 11
A19: 63598 | B19: hotel casablanca san andres sas | C19: CUBRIMIENTO | D19: 0 | F19: 2024-11-14 | G19: 2024-11-15 | H19: 2024-11-15 16:36:57 | I19: 0000-00-00 00:00:00 | J19: 2024-11-16 12:15:56 | K19: 2024-11-16 12:16:30 | L19: 0000-00-00 00:00:00 | M19: 2024-11-19 | N19: 2024-11-19 | O19: 2024-11-21 | P19: 2024-11-22 | Q19: 2024-11-22 | R19: Aprobado Facturacion | S19: Virtual | T19: 18448 | U19: FG+ESTACION INFERIOR PUERTA (DAP1721) | X19: 2 | Y19: 0 | Z19: 0 | AA19: 0 | AB19: 9000 | AC19: FINALIZADO | AD19: =+VLOOKUP(T19,items!$A$2:$D$1255,4,0) -> 0 | AE19: =+VLOOKUP(T19,Tabla1[],5,0) -> 0 | AF19: =+MONTH(O19) -> 11
A20: 63598 | B20: hotel casablanca san andres sas | C20: CUBRIMIENTO | D20: 0 | F20: 2024-11-14 | G20: 2024-11-15 | H20: 2024-11-15 16:36:57 | I20: 0000-00-00 00:00:00 | J20: 2024-11-16 12:15:56 | K20: 2024-11-16 12:16:30 | L20: 0000-00-00 00:00:00 | M20: 2024-11-19 | N20: 2024-11-19 | O20: 2024-11-21 | P20: 2024-11-22 | Q20: 2024-11-22 | R20: Aprobado Facturacion | S20: Virtual | T20: 18451 | U20: FG+TAPA IZQUIERDA BLANCA (DAP1724) | X20: 50 | Y20: 0 | Z20: 0 | AA20: 0 | AB20: 412500 | AC20: FINALIZADO | AD20: =+VLOOKUP(T20,items!$A$2:$D$1255,4,0) -> 0 | AE20: =+VLOOKUP(T20,Tabla1[],5,0) -> 0 | AF20: =+MONTH(O20) -> 11
A21: 63598 | B21: hotel casablanca san andres sas | C21: CUBRIMIENTO | D21: 0 | F21: 2024-11-14 | G21: 2024-11-15 | H21: 2024-11-15 16:36:57 | I21: 0000-00-00 00:00:00 | J21: 2024-11-16 12:15:56 | K21: 2024-11-16 12:16:30 | L21: 0000-00-00 00:00:00 | M21: 2024-11-19 | N21: 2024-11-19 | O21: 2024-11-21 | P21: 2024-11-22 | Q21: 2024-11-22 | R21: Aprobado Facturacion | S21: Virtual | T21: 18452 | U21: FG+TAPA DERECHA BLANCA (DAP1725) | X21: 50 | Y21: 0 | Z21: 0 | AA21: 0 | AB21: 412500 | AC21: FINALIZADO | AD21: =+VLOOKUP(T21,items!$A$2:$D$1255,4,0) -> 0 | AE21: =+VLOOKUP(T21,Tabla1[],5,0) -> 0 | AF21: =+MONTH(O21) -> 11
A22: 63598 | B22: hotel casablanca san andres sas | C22: CUBRIMIENTO | D22: 0 | F22: 2024-11-14 | G22: 2024-11-15 | H22: 2024-11-15 16:36:57 | I22: 0000-00-00 00:00:00 | J22: 2024-11-16 12:15:56 | K22: 2024-11-16 12:16:30 | L22: 0000-00-00 00:00:00 | M22: 2024-11-19 | N22: 2024-11-19 | O22: 2024-11-21 | P22: 2024-11-22 | Q22: 2024-11-22 | R22: Aprobado Facturacion | S22: Virtual | T22: 18453 | U22: FG+CUADRANTE (DAP1726) | X22: 30 | Y22: 0 | Z22: 0 | AA22: 0 | AB22: 47400 | AC22: FINALIZADO | AD22: =+VLOOKUP(T22,items!$A$2:$D$1255,4,0) -> 0 | AE22: =+VLOOKUP(T22,Tabla1[],5,0) -> 0 | AF22: =+MONTH(O22) -> 11
A23: 63598 | B23: hotel casablanca san andres sas | C23: CUBRIMIENTO | D23: 0 | F23: 2024-11-14 | G23: 2024-11-15 | H23: 2024-11-15 16:36:57 | I23: 0000-00-00 00:00:00 | J23: 2024-11-16 12:15:56 | K23: 2024-11-16 12:16:30 | L23: 0000-00-00 00:00:00 | M23: 2024-11-19 | N23: 2024-11-19 | O23: 2024-11-21 | P23: 2024-11-22 | Q23: 2024-11-22 | R23: Aprobado Facturacion | S23: Virtual | T23: 18455 | U23: FG+ESTACION SUPERIOR (DAP1709) | X23: 2 | Y23: 0 | Z23: 0 | AA23: 0 | AB23: 9600 | AC23: FINALIZADO | AD23: =+VLOOKUP(T23,items!$A$2:$D$1255,4,0) -> 0 | AE23: =+VLOOKUP(T23,Tabla1[],5,0) -> 0 | AF23: =+MONTH(O23) -> 11
A24: 63598 | B24: hotel casablanca san andres sas | C24: CUBRIMIENTO | D24: 0 | F24: 2024-11-14 | G24: 2024-11-15 | H24: 2024-11-15 16:36:57 | I24: 0000-00-00 00:00:00 | J24: 2024-11-16 12:15:56 | K24: 2024-11-16 12:16:30 | L24: 0000-00-00 00:00:00 | M24: 2024-11-19 | N24: 2024-11-19 | O24: 2024-11-21 | P24: 2024-11-22 | Q24: 2024-11-22 | R24: Aprobado Facturacion | S24: Virtual | T24: 18456 | U24: RETENEDOR ESTACIONAM INF PUERTA(DAP1705) | X24: 2 | Y24: 0 | Z24: 0 | AA24: 0 | AB24: 4500 | AC24: FINALIZADO | AD24: =+VLOOKUP(T24,items!$A$2:$D$1255,4,0) -> 0 | AE24: =+VLOOKUP(T24,Tabla1[],5,0) -> 0 | AF24: =+MONTH(O24) -> 11
A25: 63598 | B25: hotel casablanca san andres sas | C25: CUBRIMIENTO | D25: 0 | F25: 2024-11-14 | G25: 2024-11-15 | H25: 2024-11-15 16:36:57 | I25: 0000-00-00 00:00:00 | J25: 2024-11-16 12:15:56 | K25: 2024-11-16 12:16:30 | L25: 0000-00-00 00:00:00 | M25: 2024-11-19 | N25: 2024-11-19 | O25: 2024-11-21 | P25: 2024-11-22 | Q25: 2024-11-22 | R25: Aprobado Facturacion | S25: Virtual | T25: 18457 | U25: FG+BUJE SUPERIOR (DAP1728) | X25: 30 | Y25: 0 | Z25: 0 | AA25: 0 | AB25: 66000 | AC25: FINALIZADO | AD25: =+VLOOKUP(T25,items!$A$2:$D$1255,4,0) -> 0 | AE25: =+VLOOKUP(T25,Tabla1[],5,0) -> 0 | AF25: =+MONTH(O25) -> 11
A26: 63598 | B26: hotel casablanca san andres sas | C26: CUBRIMIENTO | D26: 0 | F26: 2024-11-14 | G26: 2024-11-15 | H26: 2024-11-15 16:36:57 | I26: 0000-00-00 00:00:00 | J26: 2024-11-16 12:15:56 | K26: 2024-11-16 12:16:30 | L26: 0000-00-00 00:00:00 | M26: 2024-11-19 | N26: 2024-11-19 | O26: 2024-11-21 | P26: 2024-11-22 | Q26: 2024-11-22 | R26: Aprobado Facturacion | S26: Virtual | T26: 18458 | U26: FG+BUJE INFERIOR (DAP1729) | X26: 30 | Y26: 0 | Z26: 0 | AA26: 0 | AB26: 73500 | AC26: FINALIZADO | AD26: =+VLOOKUP(T26,items!$A$2:$D$1255,4,0) -> 0 | AE26: =+VLOOKUP(T26,Tabla1[],5,0) -> 0 | AF26: =+MONTH(O26) -> 11
A27: 63598 | B27: hotel casablanca san andres sas | C27: CUBRIMIENTO | D27: 0 | F27: 2024-11-14 | G27: 2024-11-15 | H27: 2024-11-15 16:36:57 | I27: 0000-00-00 00:00:00 | J27: 2024-11-16 12:15:56 | K27: 2024-11-16 12:16:30 | L27: 0000-00-00 00:00:00 | M27: 2024-11-19 | N27: 2024-11-19 | O27: 2024-11-21 | P27: 2024-11-22 | Q27: 2024-11-22 | R27: Aprobado Facturacion | S27: Virtual | T27: 19544 | U27: FG+BISAGRA PUERTA ZAMAK | X27: 30 | Y27: 0 | Z27: 0 | AA27: 0 | AB27: 375000 | AC27: FINALIZADO | AD27: =+VLOOKUP(T27,items!$A$2:$D$1255,4,0) -> 0 | AE27: =+VLOOKUP(T27,Tabla1[],5,0) -> 0 | AF27: =+MONTH(O27) -> 11
A28: 63598 | B28: hotel casablanca san andres sas | C28: CUBRIMIENTO | D28: 0 | F28: 2024-11-14 | G28: 2024-11-15 | H28: 2024-11-15 16:36:57 | I28: 0000-00-00 00:00:00 | J28: 2024-11-16 12:15:56 | K28: 2024-11-16 12:16:30 | L28: 0000-00-00 00:00:00 | M28: 2024-11-19 | N28: 2024-11-19 | O28: 2024-11-21 | P28: 2024-11-22 | Q28: 2024-11-22 | R28: Aprobado Facturacion | S28: Virtual | T28: 19545 | U28: FG+BISAGRA SUPERIOR ZAMAK | X28: 30 | Y28: 0 | Z28: 0 | AA28: 0 | AB28: 360000 | AC28: FINALIZADO | AD28: =+VLOOKUP(T28,items!$A$2:$D$1255,4,0) -> 0 | AE28: =+VLOOKUP(T28,Tabla1[],5,0) -> 0 | AF28: =+MONTH(O28) -> 11
... A32: 64066 | B32: Iveth Suarez | C32: CUBRIMIENTO | D32: 0 | F32: 2024-09-20 | G32: 2024-09-20 | H32: 2024-09-23 13:29:15 | I32: 0000-00-00 00:00:00 | J32: 2024-09-23 13:29:20 | K32: 2024-09-25 09:39:40 | L32: 0000-00-00 00:00:00 | M32: 2024-09-23 | N32: 2024-09-23 | O32: 2024-09-25 | P32: 2024-09-26 | Q32: 2024-09-26 | R32: Aprobado Despachos | S32: Toscany | T32: 644041 | U32: FURNISCREEN GRIS 2M EB4027W G8 625GR | X32: 5 | Y32: 0 | Z32: 0 | AA32: 0 | AB32: 780000 | AC32: FINALIZADO | AD32: =+VLOOKUP(T32,items!$A$2:$D$1255,4,0) -> 0 | AE32: =+VLOOKUP(T32,Tabla1[],5,0) -> 0 | AF32: =+MONTH(O32) -> 9
A33: 68739 | B33: SERGIO DAZA | C33: MUEBLES CC CUBRIMIENTOS | D33: 0 | F33: 2022-01-29 | G33: 2025-10-16 | H33: 2025-10-23 13:52:43 | I33: 0000-00-00 00:00:00 | J33: 0000-00-00 00:00:00 | K33: 0000-00-00 00:00:00 | L33: 0000-00-00 00:00:00 | M33: 2025-10-17 | N33: 2025-10-17 | O33: 2025-11-12 | P33: 0000-00-00 | Q33: 2025-11-18 | R33: Aprobado Comercial | S33: Virtual | T33: 15477 | U33: MESA DE CENTRO JAPON ALUTECA 1*1(TA) | W33: Aluminio Anodizado | X33: 1 | Y33: 0 | Z33: 0 | AA33: 0 | AB33: 1754159 | AC33: DISEÑO | AD33: =+VLOOKUP(T33,items!$A$2:$D$1255,4,0) -> MUEBLES | AE33: =+VLOOKUP(T33,Tabla1[],5,0) -> 0 | AF33: =+MONTH(O33) -> 11
A34: 73280 | B34: D L K S.A.S. | C34: CUBRIMIENTO | D34: 0 | F34: 2023-11-28 | G34: 2024-11-15 | H34: 2024-11-27 10:39:54 | I34: 2024-11-30 15:09:29 | J34: 2025-02-16 19:07:50 | K34: 2025-02-25 08:19:00 | L34: 2025-04-23 11:08:04 | M34: 2024-11-27 | N34: 2024-12-07 | O34: 2025-02-23 | P34: 2025-02-26 | Q34: 2025-04-22 | R34: Aprobado Instalación | S34: Bogota | T34: 18076 | U34: SPOT ANTIGUO BLANCO / 3000K / 110V / 3W | X34: 15 | Y34: 0 | Z34: 0 | AA34: 0 | AB34: 1211250 | AC34: FINALIZADO | AD34: =+VLOOKUP(T34,items!$A$2:$D$1255,4,0) -> 0 | AE34: =+VLOOKUP(T34,Tabla1[],5,0) -> 0 | AF34: =+MONTH(O34) -> 2
A35: 73280 | B35: D L K S.A.S. | C35: CUBRIMIENTO | D35: 0 | F35: 2023-11-28 | G35: 2024-11-15 | H35: 2024-11-27 10:39:54 | I35: 2024-11-30 15:09:29 | J35: 2025-02-16 19:07:50 | K35: 2025-02-25 08:19:00 | L35: 2025-04-23 11:08:04 | M35: 2024-11-27 | N35: 2024-12-07 | O35: 2025-02-23 | P35: 2025-02-26 | Q35: 2025-04-22 | R35: Aprobado Instalación | S35: Bogota | T35: CAMBIO LONA 02 | U35: CAMBIO LONA PVC TOLDO FIJO | V35: LONA PERGOTEX TRASLUCIDA BLANCA 3M | X35: 1 | Y35: 13500 | Z35: 0 | AA35: 2500 | AB35: 8103344 | AC35: FINALIZADO | AD35: =+VLOOKUP(T35,items!$A$2:$D$1255,4,0) -> 0 | AE35: =+VLOOKUP(T35,Tabla1[],5,0) -> 0 | AF35: =+MONTH(O35) -> 2
A36: 73280 | B36: D L K S.A.S. | C36: CUBRIMIENTO | D36: 0 | F36: 2023-11-28 | G36: 2024-11-15 | H36: 2024-11-27 10:39:54 | I36: 2024-11-30 15:09:29 | J36: 2025-02-16 19:07:50 | K36: 2025-02-25 08:19:00 | L36: 2025-04-23 11:08:04 | M36: 2024-11-27 | N36: 2024-12-07 | O36: 2025-02-23 | P36: 2025-02-26 | Q36: 2025-04-22 | R36: Aprobado Instalación | S36: Bogota | T36: LONA PERGOTEK ESPECIAL02 | U36: LONA ESPECIAL PERGOTEK L13500 P5800 | V36: LONA PERGOTEX TRASLUCIDA BLANCA 3M | X36: 1 | Y36: 13500 | Z36: 0 | AA36: 5800 | AB36: 16988243 | AC36: FINALIZADO | AD36: =+VLOOKUP(T36,items!$A$2:$D$1255,4,0) -> 0 | AE36: =+VLOOKUP(T36,Tabla1[],5,0) -> 0 | AF36: =+MONTH(O36) -> 2
A37: 73280 | B37: D L K S.A.S. | C37: CUBRIMIENTO | D37: 0 | F37: 2023-11-28 | G37: 2024-11-15 | H37: 2024-11-27 10:39:54 | I37: 2024-11-30 15:09:29 | J37: 2025-02-16 19:07:50 | K37: 2025-02-25 08:19:00 | L37: 2025-04-23 11:08:04 | M37: 2024-11-27 | N37: 2024-12-07 | O37: 2025-02-23 | P37: 2025-02-26 | Q37: 2025-04-22 | R37: Aprobado Instalación | S37: Bogota | T37: SERV03 | U37: SERVICIO VIATICOS-INSTALACION CUBRIMIENT | X37: 1 | Y37: 0 | Z37: 0 | AA37: 0 | AB37: 1710000 | AC37: FINALIZADO | AD37: =+VLOOKUP(T37,items!$A$2:$D$1255,4,0) -> #N/A | AE37: =+VLOOKUP(T37,Tabla1[],5,0) -> #N/A | AF37: =+MONTH(O37) -> 2
A38: 73280 | B38: D L K S.A.S. | C38: CUBRIMIENTO | D38: 0 | F38: 2023-11-28 | G38: 2024-11-15 | H38: 2024-11-27 10:39:54 | I38: 2024-11-30 15:09:29 | J38: 2025-02-16 19:07:50 | K38: 2025-02-25 08:19:00 | L38: 2025-04-23 11:08:04 | M38: 2024-11-27 | N38: 2024-12-07 | O38: 2025-02-23 | P38: 2025-02-26 | Q38: 2025-04-22 | R38: Aprobado Instalación | S38: Bogota | T38: SERV03 | U38: SERVICIO VIATICOS-INSTALACION CUBRIMIENT | X38: 1 | Y38: 0 | Z38: 0 | AA38: 0 | AB38: 4132500 | AC38: FINALIZADO | AD38: =+VLOOKUP(T38,items!$A$2:$D$1255,4,0) -> #N/A | AE38: =+VLOOKUP(T38,Tabla1[],5,0) -> #N/A | AF38: =+MONTH(O38) -> 2
A39: 73517 | B39: LLANO DOMINGUEZ LTDA AGENCIA DE SEGUROS | C39: MUEBLES CC CUBRIMIENTOS | D39: 0 | F39: 2022-08-01 | G39: 2024-05-16 | H39: 2024-05-20 11:04:29 | I39: 0000-00-00 00:00:00 | J39: 2024-06-12 16:56:31 | K39: 2024-06-13 15:39:50 | L39: 2024-07-18 13:22:19 | M39: 2024-05-20 | N39: 2024-05-20 | O39: 2024-06-13 | P39: 2024-06-18 | Q39: 2024-06-20 | R39: Aprobado Instalación | S39: Virtual | T39: 5325 | U39: BASE METALI SOMBRILLA 400*400EN3/16"M38 | W39: Chocolate - RAL 8017 | X39: 1 | Y39: 0 | Z39: 0 | AA39: 0 | AB39: 321608 | AC39: FINALIZADO | AD39: =+VLOOKUP(T39,items!$A$2:$D$1255,4,0) -> 0 | AE39: =+VLOOKUP(T39,Tabla1[],5,0) -> 0 | AF39: =+MONTH(O39) -> 6
A40: 73517 | B40: LLANO DOMINGUEZ LTDA AGENCIA DE SEGUROS | C40: MUEBLES CC CUBRIMIENTOS | D40: 0 | F40: 2022-08-01 | G40: 2024-05-16 | H40: 2024-05-20 11:04:29 | I40: 0000-00-00 00:00:00 | J40: 2024-06-12 16:56:31 | K40: 2024-06-13 15:39:50 | L40: 2024-07-18 13:22:19 | M40: 2024-05-20 | N40: 2024-05-20 | O40: 2024-06-13 | P40: 2024-06-18 | Q40: 2024-06-20 | R40: Aprobado Instalación | S40: Virtual | T40: 8867 | U40: LONA SOMBRILLA TROPICAL 2.7 6P S/FLE | V40: LONA DICKSON ROJO VINOTINTO REF:3914 | X40: 1 | Y40: 0 | Z40: 0 | AA40: 0 | AB40: 1200000 | AC40: FINALIZADO | AD40: =+VLOOKUP(T40,items!$A$2:$D$1255,4,0) -> 0 | AE40: =+VLOOKUP(T40,Tabla1[],5,0) -> 0 | AF40: =+MONTH(O40) -> 6
A41: 73517 | B41: LLANO DOMINGUEZ LTDA AGENCIA DE SEGUROS | C41: MUEBLES CC CUBRIMIENTOS | D41: 0 | F41: 2022-08-01 | G41: 2024-05-16 | H41: 2024-05-20 11:04:29 | I41: 0000-00-00 00:00:00 | J41: 2024-06-12 16:56:31 | K41: 2024-06-13 15:39:50 | L41: 2024-07-18 13:22:19 | M41: 2024-05-20 | N41: 2024-05-20 | O41: 2024-06-13 | P41: 2024-06-18 | Q41: 2024-06-20 | R41: Aprobado Instalación | S41: Virtual | T41: REP023 | U41: REPARACION ESTRUCT SOMBRILLA MAT PRIMA | X41: 1 | Y41: 0 | Z41: 0 | AA41: 0 | AB41: 450000 | AC41: FINALIZADO | AD41: =+VLOOKUP(T41,items!$A$2:$D$1255,4,0) -> 0 | AE41: =+VLOOKUP(T41,Tabla1[],5,0) -> 0 | AF41: =+MONTH(O41) -> 6
A42: 73517 | B42: LLANO DOMINGUEZ LTDA AGENCIA DE SEGUROS | C42: MUEBLES CC CUBRIMIENTOS | D42: 0 | F42: 2022-08-01 | G42: 2024-05-16 | H42: 2024-05-20 11:04:29 | I42: 0000-00-00 00:00:00 | J42: 2024-06-12 16:56:31 | K42: 2024-06-13 15:39:50 | L42: 2024-07-18 13:22:19 | M42: 2024-05-20 | N42: 2024-05-20 | O42: 2024-06-13 | P42: 2024-06-18 | Q42: 2024-06-20 | R42: Aprobado Instalación | S42: Virtual | T42: REP031 | U42: REPARACION MESA MAT PRIMA | X42: 1 | Y42: 0 | Z42: 0 | AA42: 0 | AB42: 650000 | AC42: FINALIZADO | AD42: =+VLOOKUP(T42,items!$A$2:$D$1255,4,0) -> 0 | AE42: =+VLOOKUP(T42,Tabla1[],5,0) -> 0 | AF42: =+MONTH(O42) -> 6
A43: 73517 | B43: LLANO DOMINGUEZ LTDA AGENCIA DE SEGUROS | C43: MUEBLES CC CUBRIMIENTOS | D43: 0 | F43: 2022-08-01 | G43: 2024-05-16 | H43: 2024-05-20 11:04:29 | I43: 0000-00-00 00:00:00 | J43: 2024-06-12 16:56:31 | K43: 2024-06-13 15:39:50 | L43: 2024-07-18 13:22:19 | M43: 2024-05-20 | N43: 2024-05-20 | O43: 2024-06-13 | P43: 2024-06-18 | Q43: 2024-06-20 | R43: Aprobado Instalación | S43: Virtual | T43: REP040 | U43: REPARACION SILLA MAT PRIMA | X43: 4 | Y43: 0 | Z43: 0 | AA43: 0 | AB43: 1200000 | AC43: FINALIZADO | AD43: =+VLOOKUP(T43,items!$A$2:$D$1255,4,0) -> 0 | AE43: =+VLOOKUP(T43,Tabla1[],5,0) -> 0 | AF43: =+MONTH(O43) -> 6
...

Sheet Hoja2
A1: pedido | B1: cliente | C1: tipo_producto | D1: oportunidad | E1: razon_anulacion | F1: f_cotizacion | G1: f_pedido | H1: f_comercial | I1: f_diseno | J1: f_produccion | K1: f_despachos | L1: f_instalacion | M1: fe_comercial | N1: fe_diseno | O1: fe_produccion | P1: fe_despachos | Q1: fe_instalacion | R1: estado | S1: regional | T1: id_producto | U1: producto | V1: color | W1: color_estructura | X1: cantidad | Y1: largo | Z1: alto | AA1: proyeccion | AB1: valor_total | AC1: estado_crm | AD1: FAMILIA | AE1: LINEA | AF1: Mes Entrega
A2: 107243 | B2: industrias cattan sa | C2: MUEBLES CC CUBRIMIENTOS | D2: 0 | F2: 2025-08-19 | G2: 2025-08-21 | H2: 2025-08-28 09:37:06 | I2: 2025-10-02 08:01:53 | J2: 0000-00-00 00:00:00 | K2: 0000-00-00 00:00:00 | L2: 0000-00-00 00:00:00 | M2: 2025-08-28 | N2: 2025-10-02 | O2: 2025-11-07 | P2: 2025-11-07 | Q2: 2025-11-07 | R2: Aprobado Diseño | S2: Toscana | T2: PLITE10 | U2: PERGOLITE MAN LON VINI MUROS | V2: PENDIENTE DEFINIR CLIENTE | W2: Gris Antracita - RAL 7016 | X2: 2 | Y2: 6177 | Z2: 0 | AA2: 3553 | AB2: 6743.02 | AC2: PRODUCCION | AD2: PERGOLA | AE2: PERGOLITE | AF2: 11
A3: 107242 | B3: industrias cattan sa | C3: MUEBLES CC CUBRIMIENTOS | D3: 0 | F3: 2025-08-19 | G3: 2025-08-21 | H3: 2025-08-28 09:37:41 | I3: 2025-10-02 08:03:13 | J3: 0000-00-00 00:00:00 | K3: 0000-00-00 00:00:00 | L3: 0000-00-00 00:00:00 | M3: 2025-08-28 | N3: 2025-10-02 | O3: 2025-11-07 | P3: 2025-11-07 | Q3: 2025-11-07 | R3: Aprobado Diseño | S3: Toscana | T3: PLITE10 | U3: PERGOLITE MAN LON VINI MUROS | V3: PENDIENTE DEFINIR CLIENTE | W3: Gris Antracita - RAL 7016 | X3: 2 | Y3: 6367 | Z3: 0 | AA3: 4768 | AB3: 7589.84 | AC3: PRODUCCION | AD3: PERGOLA | AE3: PERGOLITE | AF3: 11
A4: 107070 | B4: DISEÑOS MILANELO SAS | C4: CUBRIMIENTO | D4: 0 | F4: 2025-08-13 | G4: 2025-09-26 | H4: 2025-10-29 16:57:04 | I4: 2025-11-05 18:04:07 | J4: 0000-00-00 00:00:00 | K4: 0000-00-00 00:00:00 | L4: 0000-00-00 00:00:00 | M4: 2025-10-29 | N4: 2025-11-05 | O4: 2025-11-12 | P4: 2025-11-15 | Q4: 2025-11-22 | R4: Aprobado Diseño | S4: Medellin | T4: PLITE10 | U4: PERGOLITE MAN LON VINI MUROS | V4: LONA PERGOTEX BLACKOUT BLANCA 3 M | W4: Negro Señales - RAL 9004 | X4: 5 | Y4: 4500 | Z4: 0 | AA4: 5500 | AB4: 38876835 | AC4: PRODUCCION | AD4: PERGOLA | AE4: PERGOLITE | AF4: 11

Sheet Hoja1
K7: Nota: comunicado a comercial
A16: Suma de cantidad | K16: Suma de cantidad
A17: cliente | B17: pedido | C17: producto | D17: estado | E17: largo | F17: proyeccion | G17: alto | H17: color_estructura | I17: Total | K17: producto | L17: Total
A18: BRENT SCHROEDER | B18: 106801 | C18: SOMBRALINA ELECTRICA | D18: Detenido Diseño | E18: 6000 | F18: 4000 | G18: 0 | H18: Negro Señales - RAL 9004 | I18: 3 | K18: Proyecto Especial | L18: 2
A19: GIOVANA HERNANDEZ | B19: 109111 | C19: SOMBRALINA ELECTRICA | D19: Detenido Comercial | E19: 3176 | F19: 2000 | G19: 0 | H19: Blanco Señal - RAL 9003 | I19: 2 | K19: SOMBRALINA ELECTRICA | L19: 11
A20: GONZALO HERRERA NIETO | B20: 109022 | C20: SOMBRALINA ELECTRICA | D20: Detenido Comercial | E20: 3080 | F20: 2000 | G20: 0 | H20: Blanco Señal - RAL 9003 | I20: 2 | K20: SOMBRALINA ELECTRICA MANUAL | L20: 1
A21: INDUSTRIAS ALIMENTICIAS EL TREBOL S.A.S. | B21: 108506 | C21: Proyecto Especial | D21: Detenido Comercial | E21: 0 | F21: 0 | G21: 0 | H21: (en blanco) | I21: 1 | K21: Total general | L21: 14
E22: 11570 | F22: 9870 | G22: 0 | H22: (en blanco) | I22: 1
A23: INVERSIONES DERANGO S.A.S | B23: 109490 | C23: SOMBRALINA ELECTRICA | D23: Detenido Diseño | E23: 3000 | F23: 2500 | G23: 0 | H23: Marron Tierra - RAL 8028 | I23: 1
A24: Juan Manuel Ospina Montoya | B24: 107726 | C24: SOMBRALINA ELECTRICA | D24: Detenido Comercial | E24: 5150 | F24: 3000 | G24: 0 | H24: Negro Señales - RAL 9004 | I24: 1
A25: M S L DISTRIBUCIONES & CIA S.A.S | B25: 108290 | C25: SOMBRALINA ELECTRICA | D25: En Proceso Diseño | E25: 3640 | F25: 3000 | G25: 0 | H25: Marron Tierra - RAL 8028 | I25: 1
E26: 4700 | F26: 2850 | G26: 0 | H26: Marron Tierra - RAL 8028 | I26: 1
A27: RICARDO DIAZ ROMERO | B27: 109074 | C27: SOMBRALINA ELECTRICA MANUAL | D27: Aprobado Diseño | E27: 10000 | F27: 3740 | G27: 0 | H27: Blanco Perla - RAL 1013 | I27: 1
A28: Total general | I28: 14
A122: Suma de cantidad | B122: estado_crm | C122: estado | R122: Suma de valor_total | S122: estado_crm | T122: estado
B123: COMERCIAL | C123: DISEÑO | E123: PRODUCCION | F123: Total general | S123: COMERCIAL | T123: DISEÑO | V123: PRODUCCION | W123: Total general
A124: producto | B124: Detenido Comercial | C124: Detenido Diseño | D124: En Proceso Diseño | E124: Aprobado Diseño | R124: producto | S124: Detenido Comercial | T124: Detenido Diseño | U124: En Proceso Diseño | V124: Aprobado Diseño
A125: SOMBRALINA ELECTRICA | B125: 5 | C125: 4 | D125: 2 | F125: 11 | R125: Proyecto Especial | S125: 27221976 | W125: 27221976
A126: Proyecto Especial | B126: 2 | F126: 2 | R126: SOMBRALINA ELECTRICA | S126: 27904399 | T126: 36606413 | U126: 14719408 | W126: 79230220
A127: SOMBRALINA ELECTRICA MANUAL | E127: 1 | F127: 1 | R127: SOMBRALINA ELECTRICA MANUAL | V127: 14411175 | W127: 14411175
A128: Total general | B128: 7 | C128: 4 | D128: 2 | E128: 1 | F128: 14 | R128: Total general | S128: 55126375 | T128: 36606413 | U128: 14719408 | V128: 14411175 | W128: 120863371

Sheet Hoja7
A2: riel pergoli | B2: CORTE | C2: ENSAMBLE

Sheet CAPACIDAD PLANTA
D1: centros de trabajo x persona
A2: dias habiles operación | B2: 18 | F2: 19
A3: Horas disponibles Mes | B3: =+B2*8.64 -> 155.52 | C3: =+B3/8.64 -> 18 | F3: =+F2*8.64 -> 164.16
A4: Minutos disponibles Mes | B4: =+B3*60 -> 9331.2
A5: minutos x turno | B5: 518
B9: producto | C9: Total | F9: Corte | G9: Mecanizado | H9: Pintura ** | I9: Ensamble | J9: Costura | K9: Electromecanica
B10: PERGOLITE MAN LON VINI MUROS | C10: 22 | F10: =+(22*28.8) -> 633.6 | G10: =68.8*22 -> 1513.6 | H10: =(0.113*(518))*C10 -> 1287.748 | I10: =+(41.7*22) -> 917.4 | J10: =+(31.5*22) -> 693
B11: PERGOLITE MAN LON VINI POSTES | C11: 1 | F11: 33.7 | G11: 166.4 | H11: =(0.113*(518))*C11 -> 58.534 | I11: 208.6 | J11: 31.5
B12: PERGOLITE MAN LONA ACRILICA MUROS | C12: 5 | F12: =28.8*C12 -> 144 | G12: =68.8*5 -> 344 | H12: =(0.113*(518))*C12 -> 292.67 | I12: =41.7*5 -> 208.5 | J12: =31.5*5 -> 157.5
B13: PLITE MAN LON ACRIL POSTES | C13: 1 | F13: 40.8 | G13: 152.1 | H13: =(0.113*(518))*C13 -> 58.534 | I13: 208.5 | J13: 31.5
B14: Total general | C14: 29 | E14: Total (min) | F14: =SUM(F10:F13) -> 852.1 | G14: =SUM(G10:G13) -> 2176.1 | H14: =SUM(H10:H13) -> 1697.486 | I14: =SUM(I10:I13) -> 1543 | J14: =SUM(J10:J13) -> 913.5
E15: Total (horas) | F15: =+F14/60 -> 14.201667 | G15: =+G14/60 -> 36.268333 | H15: =+H14/60 -> 28.291433 | I15: =+I14/60 -> 25.716667 | J15: =+J14/60 -> 15.225
B17: producto | C17: Total | F17: Corte | G17: Mecanizado | H17: Pintura ** | I17: Ensamble | J17: Costura | K17: Electromecanica
B18: PERGOTEK ROMANO BASIC GAZEBO | C18: 1 | E18: Total (min) | F18: 155 | G18: 224 | H18: =217*C18 -> 217 | I18: 1131
B19: PERGOTEK ROMANO MAXI GAZEBO | C19: 2 | E19: Total (horas) | F19: =+F18/60 -> 2.5833333 | G19: =+G18/60 -> 3.7333333 | H19: =+H18/60 -> 3.6166667 | I19: =+I18/60 -> 18.85
B20: PERGOTEK ROMANO MINI GAZEBO | C20: 1
B21: PERGOTEK ROMANO MINI MUROS | C21: 3
B22: Total general | C22: 7
B25: producto | C25: Total | F25: Corte | G25: Mecanizado | H25: Pintura ** | I25: Ensamble | J25: Costura | K25: Electromecanica
B26: PERGOTEK BASIC CLASSIC CON POSTES | C26: 1 | E26: Total (min) | F26: 143 | G26: 215 | H26: 217 | I26: 1108
B27: PERGOTEK MEGA CLASSIC MUROS | C27: 2 | E27: Total (horas) | F27: =+F26/60 -> 2.3833333 | G27: =+G26/60 -> 3.5833333 | H27: =+H26/60 -> 3.6166667 | I27: =+I26/60 -> 18.466667
B28: PERGOTEK MINI CLASSIC ENTRE MUROS | C28: 2
B29: PERGOTEK MINI CLASSIC POSTES | C29: 1
B30: Total general | C30: 6
B33: producto | C33: Total | F33: Corte | G33: Mecanizado | H33: Pintura ** | I33: Ensamble | J33: Costura | K33: Electromecanica
B34: MAXI PERGOLAM CON POSTES | C34: 6 | F34: =644*C34 -> 3864 | G34: =203*C34 -> 1218 | H34: =1295*C34 -> 7770 | I34: =1813*C34 -> 10878 | K34: =1984*C34 -> 11904
B35: MAXI PERGOLAM ENTRE MUROS | C35: 6 | F35: =659*C35 -> 3954 | G35: =266.9*C35 -> 1601.4 | H35: =1295*C35 -> 7770 | I35: =1759*C35 -> 10554 | K35: =1984*C35 -> 11904
B36: MAXI PERGOLAM GAZEBO | C36: 2 | F36: =677.8*C36 -> 1355.6 | G36: =232.3*C36 -> 464.6 | H36: =1295*C36 -> 2590 | I36: =1867*C36 -> 3734 | K36: =1984*C36 -> 3968
B37: Total general | C37: 14 | E37: Total (min) | F37: =SUM(F34:F36) -> 9173.6 | G37: =SUM(G34:G36) -> 3284 | H37: =SUM(H34:H36) -> 18130 | I37: =SUM(I34:I36) -> 25166 | J37: =SUM(J34:J36) -> 0 | K37: =SUM(K34:K36) -> 27776
E38: Total (horas) | F38: =+F37/60 -> 152.89333 | G38: =+G37/60 -> 54.733333 | H38: =+H37/60 -> 302.16667 | I38: =+I37/60 -> 419.43333 | J38: =+J37/60 -> 0 | K38: =+K37/60 -> 462.93333
F40: Corte | G40: Mecanizado | H40: Pintura ** | I40: Ensamble | J40: Costura | K40: Electromecanica
C41: Total Horas Necesarias | E41: Total (min) | F41: =+F14+F18+F26+F37 -> 10323.7 | G41: =+G14+G18+G26+G37 -> 5899.1 | H41: =+H14+H18+H26+H37 -> 20261.486 | I41: =+I14+I18+I26+I37 -> 28948 | J41: =+J14+J18+J26+J37 -> 913.5 | K41: =+K14+K18+K26+K37 -> 27776
E42: Total (horas) | F42: =+F41/60 -> 172.06167 | G42: =+G41/60 -> 98.318333 | H42: =+H41/60 -> 337.69143 | I42: =+I41/60 -> 482.46667 | J42: =+J41/60 -> 15.225 | K42: =+K41/60 -> 462.93333
E43: Total (dias) | F43: =+F42/8.64 -> 19.914545 | G43: =+G42/8.64 -> 11.379437 | H43: =+H42/8.64 -> 39.084657 | I43: =+I42/8.64 -> 55.841049 | J43: =+J42/8.64 -> 1.7621528 | K43: =+K42/8.64 -> 53.580247
E44: Operarios | F44: 1 | G44: 1 | H44: 1 | I44: 4 | J44: 5 | K44: 1
E45: Total (min) | F45: =+F41/F44 -> 10323.7 | G45: =+G41/G44 -> 5899.1 | H45: =+H41/H44 -> 20261.486 | I45: =+I41/I44 -> 7237 | J45: =+J41/J44 -> 182.7 | K45: =+K41/K44 -> 27776
E46: Total (horas) | F46: =+F45/60 -> 172.06167 | G46: =+G45/60 -> 98.318333 | H46: =+H45/60 -> 337.69143 | I46: =+I45/60 -> 120.61667 | J46: =+J45/60 -> 3.045 | K46: =+K45/60 -> 462.93333
E47: Total (dias) | F47: =+F46/8.64 -> 19.914545 | G47: =+G46/8.64 -> 11.379437 | H47: =+H46/8.64 -> 39.084657 | I47: =+I46/8.64 -> 13.960262 | J47: =+J46/8.64 -> 0.35243056 | K47: =+K46/8.64 -> 53.580247
F48: 155 | G48: 155 | H48: 155 | I48: 155 | J48: 155 | K48: 155
B49: DICIEMBRE | F49: =+F48-F46 -> -17.061667 | G49: =+G48-G46 -> 56.681667 | H49: =+H48-H46 -> -182.69143 | I49: =+I48-I46 -> 34.383333 | J49: =+J48-J46 -> 151.955 | K49: =+K48-K46 -> -307.93333
...

Sheet items
A1: id_producto | B1: producto | C1: CLASIFICACION | D1: FAMILIA | E1: LINEA
A2: 98731 | B2: ACOPLE DESPL. SUP. MASTIL. SOMBR. ROMA.
A3: REP045 | B3: REPARACION SOMBRILLA MANO OBRA
A4: 15477 | B4: MESA DE CENTRO JAPON ALUTECA 1*1(TA) | C4: PRODUCTO TERMINADO | D4: MUEBLES
A5: 15479 | B5: SOFA JAPON ALUTECA TRES PUESTOS C/C | C5: PRODUCTO TERMINADO | D5: MUEBLES
A6: 15481 | B6: POLTRONA JAPON ALUTECA C/C | C6: PRODUCTO TERMINADO | D6: MUEBLES
A7: 19353 | B7: PASADOR PUERTA CONICO P/FLEXIGLASS
A8: FGLASS01 | B8: FLEXIGLASS 10 mm | C8: PRODUCTO TERMINADO | D8: FLEXIGLASS
A9: 2043 | B9: MESA BISTRO 0.70*0.70 C/BM (TL) | C9: PRODUCTO TERMINADO | D9: MUEBLES
A10: PFAT07 | B10: PERGOLA FIJA ACEROTECA GRANDE | C10: PRODUCTO TERMINADO | D10: PERGOLA | E10: PERGOLA FIJA
A11: PLAM05 | B11: MAXI PERGOLAM CON POSTES | C11: PRODUCTO TERMINADO | D11: PERGOLA | E11: MAXI PERGOLAM
A12: 18013 | B12: TORN PRIS 8mmX8 DIAM P/FLEXIGLASS PLUS
A13: 18447 | B13: FG+STACION SUPERIOR PUERTA (DAP1720)
A14: 18448 | B14: FG+ESTACION INFERIOR PUERTA (DAP1721)
A15: 18451 | B15: FG+TAPA IZQUIERDA BLANCA (DAP1724)
A16: 18452 | B16: FG+TAPA DERECHA BLANCA (DAP1725)
A17: 18453 | B17: FG+CUADRANTE (DAP1726)
A18: 18455 | B18: FG+ESTACION SUPERIOR (DAP1709)
A19: 18456 | B19: RETENEDOR ESTACIONAM INF PUERTA(DAP1705)
A20: 18457 | B20: FG+BUJE SUPERIOR (DAP1728)
A21: 18458 | B21: FG+BUJE INFERIOR (DAP1729)
A22: 19544 | B22: FG+BISAGRA PUERTA ZAMAK
A23: 19545 | B23: FG+BISAGRA SUPERIOR ZAMAK
... A37: 6277 | B37: LONA PERGOTEX BLACKOUT BLANCA 3 M
A38: 6752 | B38: FUNDA SOMBRILLA ROMA 3.0 X 3.0M | C38: PRODUCTO TERMINADO | D38: FUNDA
A39: PTEKROM12 | B39: PERGOTEK ROMANO MINI MUROS | C39: PRODUCTO TERMINADO | D39: PERGOLA | E39: PERGOTEK ROMANO
A40: 180331 | B40: CINTA ALUMINIO 25mmX33mts
A41: 25769 | B41: SELLADOR ADHESIVO PU 50 BLANCO 600 ML SA
A42: REP035 | B42: REPARACION PERGOLA MAT PRIMA
A43: 13672 | B43: ASOLEADORA VICHADA (TA) | C43: PRODUCTO TERMINADO | D43: MUEBLES
A44: TRANSP07 | B44: TRANSPORTE FUERA DE CALI MUEBLES
A45: REP029 | B45: REPARACION MEMBRANA MANO OBRA
A46: REP030 | B46: REPARACION MEMBRANA MAT PRIMA
A47: FLANCHE01 | B47: FLANCHE NACIONAL GALVANIZADO
A48: PLT45 | B48: PLATINA ANCLAJE POSTEMURO PERF.127x127
A49: PTEKROM02 | B49: PERGOTEK ROMANO MEGA MUROS | C49: PRODUCTO TERMINADO | D49: PERGOLA | E49: PERGOTEK ROMANO
A50: SPOT30 | B50: SISTEMA ELECTRICO 30 SPOT PARA PERGOLA
A51: PLAM08 | B51: MAXI PERGOLAM GAZEBO | C51: PRODUCTO TERMINADO | D51: PERGOLA | E51: MAXI PERGOLAM
A52: 9683 | B52: MALLA SILLA VENUS
A53: 3151 | B53: CORREA DENTADA 19mm PERGOLAS RETRACTILES
...
